Workbook

Sheet Read Me
A1: Accessibility inventory and scope template
A2: https://github.com/architecting-accessibility/book
A3: Purpose | B3: Inventory technologies/products, map applicable legal/policy regimes, record technical baselines, exemptions/exceptions, ownership and verification.
A4: Important | B4: The Legal Register is a curated global starting point, not exhaustive legal advice. Requirements change and depend on entity, sector, jurisdiction, product/service and date. Verify applicability and exemptions with qualified legal counsel.
A5: Legal hierarchy | B5: Use Parent framework and Relationship notes to distinguish supranational frameworks (e.g. WAD/EAA) from national implementations or technical frameworks (e.g. France Article 47 + RGAA).
A6: Exemptions / exceptions | B6: Do not assume exemptions transfer between laws. The Inventory records status; the Legal Register records law-specific examples. Copy the exact legal basis into the inventory and have it reviewed.
A7: Multiple laws | B7: Use Primary Legal / Policy plus Additional Legal / Policy 1 and 2. Add more in Notes if needed.
A8: Baselines | B8: A law and a technical baseline are not the same thing. Record both separately.
A9: Suggested workflow | B9: 1) Inventory technology. 2) Determine users/jurisdictions. 3) Select regimes. 4) Set baseline. 5) Document exemptions/exceptions. 6) Assign owner. 7) Define verification. 8) Review periodically.
A10: W3C cross-check | B10: https://www.w3.org/WAI/policies/
A11: Reporting | B11: Live summary of the inventory (totals, completeness checks, breakdowns, charts). All figures are formulas and update as rows are added; ranges cover inventory rows 2-1000.
A12: Review Log | B12: Findings from the accuracy review of the inventory, lookups and legal register: what was changed, and what still needs a human decision or legal verification.
A13: Legal regime list | B13: Lookups column M is now a formula that reads Legal Register column D. Add new laws to the Legal Register first, then extend the Lookups column M formulas and the validation range.

Sheet Accessibility Inventory
A1: Asset / technology | B1: Description / example | C1: Category | D1: Product scope | E1: Platform | F1: Audience | G1: Lifecycle | H1: Scope status | I1: Primary legal / policy | J1: Additional legal / policy 1 | K1: Additional legal / policy 2 | L1: Accessibility baseline | M1: Exception / exemption status | N1: Exception / exemption basis | O1: Primary owner / team | P1: Supporting owner / team | Q1: Verification method | R1: Criticality | S1: Dependency / vendor | T1: Target / review date | U1: Notes
A2: Customer account portal | B2: Authenticated customer self-service portal | C2: Web application | D2: Single product | E2: Responsive web | F2: Customers | G2: Live / maintained | H2: In scope | I2: European Accessibility Act — Directive (EU) 2019/882 (EAA) | L2: WCAG 2.2 Level AA | M2: None identified | O2: Product manager | P2: Frontend engineering | Q2: Combination of methods | R2: Critical — essential service / core journey | S2: First-party | U2: Example only — determine actual service/jurisdiction scope.
A3: Payment checkout | B3: Third-party hosted card payment flow | C3: Payment/checkout | D3: Vendor service | E3: Responsive web | F3: Customers | G3: Procured / vendor-hosted | H3: In scope | I3: US — ADA Title II Web & Mobile Accessibility Rule (2024) | L3: WCAG 2.1 Level AA | M3: Potential exemption / exception — legal review | N3: Do not assume vendor ownership removes your obligations; review exact service scope and contract. | O3: Procurement / vendor management | P3: Product manager | Q3: Vendor accessibility evidence | R3: Critical — essential service / core journey | S3: Vendor-hosted | U3: Example of vendor dependency.
A4: Employee HR portal | B4: Internal HR and payroll self-service | C4: Internal tool | D4: Enterprise-wide capability | E4: Responsive web | F4: Employees | G4: Live / maintained | H4: Pending assessment | I4: UK — Equality Act 2010 | L4: WCAG 2.2 Level AA | M4: Unknown / pending review | N4: Employment-related duties are context-specific. | O4: IT / internal systems | P4: Legal / compliance | Q4: Combination of methods | R4: High — frequent or revenue-impacting | S4: Mixed | U4: Example only.
A5: Public-sector service website | B5: Citizen-facing forms and transactions | C5: Public website | D5: Customer journey | E5: Responsive web | F5: General public | G5: Live / maintained | H5: In scope | I5: EU Web Accessibility Directive (EU) 2016/2102 (WAD) | J5: France — Article 47, Law No. 2005-102 + RGAA | L5: RGAA (current version) | M5: Potential exemption / exception — legal review | O5: Product owner | P5: Accessibility specialist | Q5: Expert audit | R5: Critical — essential service / core journey | S5: First-party | U5: Illustrates parent + national implementation.

Sheet Legal Register
A1: Region | B1: Jurisdiction | C1: Parent framework | D1: Law / policy / standard | E1: Instrument type | F1: Typical scope | G1: Technical baseline / reference | H1: Key exemptions / exceptions (summary) | I1: Relationship / implementation notes | J1: Official / authoritative source
A2: Europe | B2: European Union | D2: EU Web Accessibility Directive (EU) 2016/2102 (WAD) | E2: Directive / accessibility law | F2: Public-sector websites and mobile apps | G2: EN 301 549 / harmonised standard; web requirements map to WCAG | H2: Excluded content categories include certain office files, pre-recorded media, live media, online maps (with accessible essential information), third-party content outside control, heritage reproductions, and archives; disproportionate burden may be invoked subject to assessment. | I2: Parent EU framework implemented/transposed by Member States for public-sector web/mobile accessibility. | J2: https://eur-lex.europa.eu/eli/dir/2016/2102/oj
A3: Europe | B3: European Union | D3: European Accessibility Act — Directive (EU) 2019/882 (EAA) | E3: Directive / accessibility law | F3: Specified products and services in public and private sectors | G3: Harmonised standards/common specifications; EN 301 549 is relevant to ICT accessibility | H3: Microenterprises providing services are exempt; requirements do not apply where they would cause a fundamental alteration or impose a disproportionate burden, subject to conditions/documentation. Transitional measures also apply. | I3: Parent EU framework transposed into national law by Member States; applies from 28 June 2025 to covered products/services. | J3: https://eur-lex.europa.eu/eli/dir/2019/882/oj
A4: Europe | B4: France | C4: EU WAD 2016/2102; French disability law | D4: France — Article 47, Law No. 2005-102 + RGAA | E4: National accessibility law + technical reference framework | F4: Public bodies and specified private entities / online public communication services | G4: RGAA; harmonised standards referenced by French implementing decree | H4: Disproportionate burden; certain content exclusions tied to WAD/EAA categories; some nonprofit private bodies outside specified essential/disability-focused services may be outside scope. Verify current turnover thresholds and amendments. | I4: RGAA operationalises French digital-accessibility requirements. Article 47 and implementing decrees align with WAD; RGAA is not simply the French transposition of the EAA. | J4: https://www.legifrance.gouv.fr/loda/article_lc/LEGIARTI000048050213
A5: Europe | B5: Germany | C5: EU WAD 2016/2102 | D5: Germany — BITV 2.0 | E5: Federal accessibility ordinance | F5: German federal public-sector ICT/web | G5: BITV 2.0 / applicable harmonised standards | H5: Law-specific exclusions and disproportionate-burden provisions should be checked against current BITV/BGG. | I5: Federal implementation framework for accessible information technology under German disability-equality law. | J5: https://www.gesetze-im-internet.de/bitv_2_0/
A6: Europe | B6: Italy | C6: EU WAD 2016/2102 | D6: Italy — Law No. 4/2004 (Stanca Law), as amended | E6: Accessibility law | F6: Public administration and other covered entities | G6: AgID requirements / EN 301 549 / WCAG-derived criteria | H6: Specific scope and exemptions depend on entity and service; WAD-related disproportionate burden/excluded content rules may apply. | I6: Italy's principal digital-accessibility law; amended for EU public-sector accessibility obligations. | J6: https://www.agid.gov.it/en/design-servizi/accessibilita
A7: Europe | B7: Spain | C7: EU WAD 2016/2102 | D7: Spain — Royal Decree 1112/2018 | E7: Accessibility law | F7: Public-sector websites and mobile applications | G7: EN 301 549 / harmonised standards | H7: Excluded content and disproportionate-burden mechanism reflect WAD; users may request accessible information for excluded/exempt content where reasonable and legitimate. | I7: Spanish implementation of WAD. | J7: https://www.boe.es/buscar/act.php?id=BOE-A-2018-12699
A8: Europe | B8: Ireland | C8: EU WAD 2016/2102 | D8: Ireland — S.I. No. 358/2020 Accessibility Regulations | E8: Accessibility regulations | F8: Public-sector websites and mobile apps | G8: EN 301 549 / WCAG-derived requirements | H8: WAD content exclusions and disproportionate-burden provisions apply; verify exact wording in current instrument. | I8: Irish implementation of WAD. | J8: https://www.irishstatutebook.ie/eli/2020/si/358/made/en/print
A9: Europe | B9: Sweden | C9: EU WAD 2016/2102 | D9: Sweden — Act (2018:1937) on accessibility to digital public services | E9: Accessibility law | F9: Government/public-sector digital services | G9: EN 301 549 / harmonised standards | H9: WAD-derived exclusions and disproportionate-burden rules. | I9: Swedish implementation of WAD. | J9: https://www.w3.org/WAI/policies/sweden/
A10: Europe | B10: Finland | C10: EU WAD 2016/2102 | D10: Finland — Act on the Provision of Digital Services (306/2019) | E10: Accessibility law | F10: Public-sector and certain other digital services | G10: EN 301 549 / WCAG-derived requirements | H10: Content exclusions and disproportionate burden; exact scope differs by provider/service. | I10: Implements WAD and national digital-service requirements. | J10: https://www.w3.org/WAI/policies/finland/
A11: Europe | B11: Denmark | C11: EU WAD 2016/2102 | D11: Denmark — Web Accessibility Act | E11: Accessibility law | F11: Government/public-sector websites and mobile apps | G11: EN 301 549 / WCAG-derived requirements | H11: WAD-derived exclusions and disproportionate-burden provisions. | I11: Danish implementation of WAD. | J11: https://www.w3.org/WAI/policies/denmark/
A12: Europe | B12: Belgium | C12: EU WAD 2016/2102 | D12: Belgium — Law on accessibility of websites and mobile applications of public bodies (2018) | E12: Accessibility law | F12: Public-sector websites and mobile apps | G12: EN 301 549 / WCAG-derived requirements | H12: WAD-derived exclusions and disproportionate-burden provisions; federal/regional competence can affect applicability. | I12: Belgian implementation of WAD. | J12: https://www.w3.org/WAI/policies/belgium/
A13: Europe | B13: Netherlands | C13: EU WAD 2016/2102 | D13: Netherlands — public-sector digital accessibility decree/rules | E13: Accessibility law / mandatory policy | F13: Government/public-sector websites and mobile apps | G13: EN 301 549 / WCAG 2.1-derived requirements | H13: WAD-derived exclusions and disproportionate-burden provisions. | I13: Dutch implementation framework for WAD. | J13: https://www.w3.org/WAI/policies/netherlands/
A14: Europe | B14: Poland | C14: EU WAD 2016/2102 | D14: Poland — Act of 4 April 2019 on digital accessibility | E14: Accessibility law | F14: Government/public-sector websites and mobile apps | G14: EN 301 549 / WCAG-derived requirements | H14: WAD-derived exclusions and disproportionate-burden provisions. | I14: Polish implementation of WAD. | J14: https://www.w3.org/WAI/policies/poland/
A15: Europe | B15: Portugal | C15: EU WAD 2016/2102 | D15: Portugal — Decreto-Lei n.º 83/2018 | E15: Accessibility law | F15: Public-sector websites and mobile apps | G15: EN 301 549 / harmonised standards | H15: WAD-derived content exclusions and disproportionate-burden provisions. | I15: Portuguese transposition of WAD. | J15: https://www.w3.org/WAI/policies/portugal/
A16: Europe | B16: United Kingdom | C16: Former EU WAD-derived regime | D16: UK — Public Sector Bodies Accessibility Regulations 2018 | E16: Accessibility regulations | F16: Public-sector websites and mobile apps | G16: WCAG 2.2 AA in current UK government guidance | H16: Specified organisation/content exemptions include broadcasters, some schools/nurseries, older media/documents, maps with accessible essential information, certain third-party content, older intranet/extranet content and archives; disproportionate burden may be assessed. | I16: UK domestic public-sector regime derived from WAD. | J16: https://www.gov.uk/guidance/accessibility-requirements-for-public-sector-websites-and-apps
A17: Europe | B17: United Kingdom | D17: UK — Equality Act 2010 | E17: Non-discrimination law | F17: Service providers, employers and others in Great Britain | G17: No single WCAG level specified by the Act | H17: Reasonable-adjustment duty is context-dependent; separate law applies in Northern Ireland. | I17: Broader anti-discrimination duty that can apply to digital services; distinct from public-sector web regulations. | J17: https://www.legislation.gov.uk/ukpga/2010/15/contents
A18: North America | B18: United States | D18: US — Americans with Disabilities Act (ADA) | E18: Federal non-discrimination law | F18: State/local government and places of public accommodation, among others | G18: ADA itself does not set one WCAG version for all private-sector web contexts | H18: Undue burden/fundamental alteration and other exceptions/defenses are context-specific. Private web applicability depends on service and jurisdiction. | I18: Umbrella US disability-rights law; 2024 Title II rule separately sets a technical standard for state/local government. | J18: https://www.ada.gov/law-and-regs/ada/
A19: North America | B19: United States | C19: ADA Title II | D19: US — ADA Title II Web & Mobile Accessibility Rule (2024) | E19: Federal accessibility regulation | F19: State and local government web content and mobile apps | G19: WCAG 2.1 Level AA | H19: Specific exceptions include certain archived content, some preexisting conventional electronic documents, third-party content, individualized password-protected documents and preexisting social-media posts, subject to conditions; ADA undue burden/fundamental alteration remain relevant. | I19: Specific technical rule under ADA Title II. | J19: https://www.ada.gov/resources/2024-03-08-web-rule/
A20: North America | B20: United States | C20: Rehabilitation Act | D20: US — Section 508 of the Rehabilitation Act | E20: Federal accessibility / procurement law | F20: US federal agencies' ICT developed, procured, maintained or used | G20: Revised Section 508 Standards; WCAG 2.0 A/AA incorporated | H20: Defined exceptions include national security systems and certain incidental ICT; undue burden and fundamental alteration provisions may apply with documentation and alternative access duties. | I20: Federal ICT accessibility regime including procurement. | J20: https://www.section508.gov/manage/laws-and-policies/section-508-law/
A21: North America | B21: United States | D21: US — Air Carrier Access Act web/kiosk accessibility rule | E21: Sector-specific accessibility regulation | F21: Covered airlines and airport kiosks/websites in specified contexts | G21: WCAG 2.0 Level AA for covered website requirements | H21: Sector-specific scope, deadlines and exceptions; verify current DOT rules. | I21: Sector-specific federal accessibility obligations. | J21: https://www.transportation.gov/airconsumer/air-travelers-disabilities
A22: North America | B22: United States | D22: US — 21st Century Communications and Video Accessibility Act (CVAA) | E22: Sector-specific accessibility law | F22: Advanced communications/video programming and related equipment/services | G22: FCC accessibility rules; some requirements reference ICT standards | H22: Product/service-specific exceptions and achievable/technical-feasibility concepts may apply; verify FCC rules. | I22: Sector-specific federal obligations administered by FCC. | J22: https://www.fcc.gov/consumers/guides/21st-century-communications-and-video-accessibility-act-cvaa
A23: North America | B23: Canada | D23: Canada — Accessible Canada Act (ACA) | E23: Federal accessibility law | F23: Federally regulated entities and federal government | G23: Standards/regulations; CAN/ASC-EN 301 549:2024 supports ACA goals | H23: Applicability depends on federally regulated status and implementing regulations; entity-specific exemptions should be verified. | I23: Federal barrier-removal framework. | J23: https://laws-lois.justice.gc.ca/eng/acts/A-0.6/
A24: North America | B24: Canada | C24: Accessible Canada Act / standards ecosystem | D24: Canada — CAN/ASC-EN 301 549:2024 | E24: National standard | F24: ICT products and services | G24: CAN/ASC-EN 301 549:2024 | H24: Technical standard rather than blanket statutory obligation; applicability comes from law, procurement, policy or contract. | I24: Canadian adoption of EN 301 549:2021 as a National Standard of Canada. | J24: https://accessible.canada.ca/standards-and-technical-guides/standards-and-technical-guides-database/can-asc-en-301-5492024-accessibility-requirements-ict-products-and-services-en-301-5492021-idt
A25: North America | B25: Canada — Ontario | C25: AODA | D25: Ontario — AODA web accessibility requirements | E25: Provincial accessibility law/regulation | F25: Designated public sector and organisations with 50+ employees controlling public websites | G25: WCAG 2.0 Level AA with specified exceptions | H25: Ontario guidance excludes WCAG 2.0 SC 1.2.4 and 1.2.5; internal sites are not subject to the same public-web requirement; applicability includes employee-count/content-date conditions. | I25: Provincial regime under AODA. | J25: https://www.ontario.ca/page/how-make-websites-accessible
A26: Oceania | B26: Australia | D26: Australia — Disability Discrimination Act 1992 (DDA) | E26: Federal non-discrimination law | F26: Government, public and private sectors | G26: No single WCAG version in the Act; AHRC guidance is WCAG-based | H26: Unjustifiable hardship and other statutory concepts may be relevant; context-specific legal review required. | I26: Broad anti-discrimination law relevant to digital access. | J26: https://humanrights.gov.au/our-work/disability-rights/disability-discrimination
A27: Oceania | B27: Australia | C27: Australian Government policy | D27: Australia — Digital Experience Policy / Digital Service Standard | E27: Mandatory government policy / standard | F27: Australian Government digital services | G27: WCAG 2.2 in current policy ecosystem | H27: Policy scope/exceptions depend on agency/service classification. | I27: Government digital policy requiring inclusive digital experiences. | J27: https://www.digital.gov.au/policy/digital-experience
A28: Oceania | B28: Australia | C28: Commonwealth procurement framework | D28: Australia — Commonwealth Procurement Rules + AS EN 301 549 | E28: Procurement policy / ICT accessibility standard | F28: Commonwealth ICT procurement | G28: AS EN 301 549 | H28: Procurement exemptions/entity rules depend on CPR and context. | I28: Accessible ICT procurement framework. | J28: https://www.finance.gov.au/government/procurement/commonwealth-procurement-rules
A29: Oceania | B29: New Zealand | D29: New Zealand — Human Rights Act 1993 | E29: Non-discrimination law | F29: Public and private sectors | G29: No single WCAG level specified by Act | H29: Anti-discrimination/reasonable-accommodation analysis is context-specific. | I29: Broad non-discrimination framework. | J29: https://www.legislation.govt.nz/act/public/1993/0082/latest/DLM304212.html
A30: Oceania | B30: New Zealand | C30: NZ Government digital standards | D30: New Zealand — Government Web Accessibility Standard | E30: Mandatory government standard | F30: Specified Executive-branch public-service departments | G30: NZ Government Web Accessibility Standard / WCAG-derived | H30: The standard contains documented exceptions; verify the current version and conformance requirements. | I30: Mandatory government web standard. | J30: https://www.digital.govt.nz/standards-and-guidance/design-and-ux/accessibility
A31: Asia | B31: Japan | D31: Japan — Act for Eliminating Discrimination against Persons with Disabilities | E31: Non-discrimination law | F31: Public and private sectors | G31: Does not itself mandate JIS X 8341-3 for all web content | H31: Reasonable-accommodation obligations/exceptions are context-specific. | I31: Broad disability non-discrimination framework. | J31: https://www8.cao.go.jp/shougai/english/law/no-discrimination.html
A32: Asia | B32: Japan | C32: Japanese public-sector web policy | D32: Japan — JIS X 8341-3:2016 + Everyone's Public Website Guidelines | E32: National standard + public-sector guidance | F32: Web content, especially public-sector practice | G32: JIS X 8341-3:2016; Digital Agency practice also references WCAG 2.2 | H32: JIS is not a blanket statutory mandate for all websites; applicability depends on policy/organisation. | I32: Japanese web-accessibility standard and government guidance. | J32: https://www.w3.org/WAI/policies/japan/
A33: Asia | B33: India | D33: India — Rights of Persons with Disabilities Act 2016 | E33: Disability-rights law | F33: Public and private sectors in covered contexts | G33: Rules/standards and government guidance determine technical implementation | H33: Statutory exceptions and implementation depend on context; verify current rules. | I33: Umbrella disability-rights framework relevant to accessible ICT/information. | J33: https://depwd.gov.in/acts/
A34: Asia | B34: India | C34: Government digital policy | D34: India — Guidelines for Indian Government Websites / Apps (GIGW) | E34: Mandatory government guideline | F34: Indian government websites/apps | G34: Current GIGW accessibility requirements reference WCAG/government standards | H34: Scope/exceptions should be checked in current GIGW version. | I34: Operational requirements for Indian government digital properties. | J34: https://guidelines.india.gov.in/
A35: Asia | B35: Republic of Korea | D35: Republic of Korea — disability accessibility framework | E35: Non-discrimination / accessibility law | F35: Public and private sectors in covered contexts | G35: Korean web-content accessibility standards are WCAG-derived | H35: Applicability/exceptions depend on statute, entity and service. | I35: National disability-rights framework supported by Korean web standards. | J35: https://www.w3.org/WAI/policies/korea/
A36: Asia | B36: China | D36: China — Law on Protection of Persons with Disabilities + digital accessibility standards | E36: Accessibility / disability-rights law | F36: Public and private sectors | G36: National accessibility standards/policies; not one WCAG mandate | H36: Scope and implementing standards are context-specific. | I36: Umbrella disability-rights law plus separate digital accessibility standards/policies. | J36: https://www.w3.org/WAI/policies/china/
A37: Asia | B37: Hong Kong SAR | C37: Hong Kong government policy | D37: Hong Kong — Government web accessibility guidance | E37: Government policy / guidance | F37: Government websites and digital services | G37: WCAG-based government requirements | H37: Policy-specific scope/exceptions; verify current Digital Policy Office guidance. | I37: Government policy rather than general private-sector web statute. | J37: https://www.digitalpolicy.gov.hk/en/our_work/digital_government/policies_standards/web_accessibility/
A38: Middle East | B38: Israel | D38: Israel — Equal Rights for Persons with Disabilities framework + web accessibility regulations | E38: Non-discrimination / accessibility regulation | F38: Public and private service providers in covered contexts | G38: Israeli Standard SI 5568, historically WCAG-based | H38: Small-business/technical-feasibility/service-specific provisions may apply; verify current regulation. | I38: National disability-rights law with detailed accessibility regulations. | J38: https://www.w3.org/WAI/policies/israel/
A39: South America | B39: Brazil | D39: Brazil — Brazilian Law of Inclusion (Law No. 13.146/2015) | E39: Disability-rights / accessibility law | F39: Public and private sectors in covered contexts | G39: Brazilian accessibility standards/guidance; eMAG for government | H39: Law-specific applicability/exceptions should be checked; website accessibility is expressly addressed. | I39: National disability-inclusion law. | J39: https://www.planalto.gov.br/ccivil_03/_ato2015-2018/2015/lei/l13146.htm
A40: South America | B40: Brazil | C40: Brazilian federal e-government policy | D40: Brazil — eMAG | E40: Government accessibility model / policy | F40: Federal government digital services | G40: eMAG, WCAG-derived | H40: Government-policy scope; check current eMAG rules and agency obligations. | I40: Operational model for Brazilian government accessibility. | J40: https://www.gov.br/governodigital/pt-br/acessibilidade-e-usuario/acessibilidade-digital/emag
...

Sheet Lookups
A1: Category | B1: Product scope | C1: Platform | D1: Audience | E1: Lifecycle | F1: Scope status | G1: Baseline | H1: Exception status | I1: Owner / team | J1: Verification | K1: Criticality | L1: Dependency | M1: Legal / policy regime
A2: Public website | B2: Single feature | C2: Responsive web | D2: General public | E2: New / planned | F2: In scope | G2: WCAG 2.2 Level AA | H2: None identified | I2: Product manager | J2: Automated accessibility tests | K2: Critical — essential service / core journey | L2: First-party | M2: ='Legal Register'!D2 -> EU Web Accessibility Directive (EU) 2016/2102 (WAD)
A3: Web application | B3: Single product | C3: Desktop web | D3: Customers | E3: In design | F3: Out of scope — documented basis | G3: WCAG 2.1 Level AA | H3: Potential exemption / exception — legal review | I3: Product owner | J3: Manual keyboard testing | K3: High — frequent or revenue-impacting | L3: Third-party | M3: ='Legal Register'!D3 -> European Accessibility Act — Directive (EU) 2019/882 (EAA)
A4: Native mobile app | B4: Product family | C4: Mobile web | D4: Prospective customers | E4: In development | F4: Pending assessment | G4: WCAG 2.0 Level AA | H4: Exemption / exception applies — documented | I4: Engineering manager | J4: Screen reader testing | K4: Medium — important but workaround exists | L4: Mixed | M4: ='Legal Register'!D4 -> France — Article 47, Law No. 2005-102 + RGAA
A5: Hybrid mobile app | B5: Shared platform | C5: iOS | D5: Employees | E5: Pre-release | F5: Partially in scope | G5: EN 301 549 (current applicable version) | H5: Disproportionate / undue burden claimed | I5: Frontend engineering | J5: Zoom / reflow testing | K5: Low — ancillary | L5: Open-source dependency | M5: ='Legal Register'!D5 -> Germany — BITV 2.0
A6: Desktop application | B6: Enterprise-wide capability | C6: Android | D6: Job applicants | E6: Pilot / beta | G6: CAN/ASC-EN 301 549:2024 | H6: Fundamental alteration claimed | I6: Backend engineering | J6: Colour / contrast review | K6: Unknown / assess | L6: Vendor-hosted | M6: ='Legal Register'!D6 -> Italy — Law No. 4/2004 (Stanca Law), as amended
A7: Document/PDF | B7: Customer journey | C7: Windows | D7: Partners/suppliers | E7: Live / maintained | G7: Section 508 Revised Standards | H7: Legacy / archived content exclusion | I7: Mobile engineering | J7: Design review | L7: Unknown | M7: ='Legal Register'!D7 -> Spain — Royal Decree 1112/2018
A8: Email/template | B8: Document set | C8: macOS | D8: Administrators | E8: Legacy / maintained | G8: RGAA (current version) | H8: Microenterprise / small-provider exemption | I8: Platform engineering | J8: Code review | M8: ='Legal Register'!D8 -> Ireland — S.I. No. 358/2020 Accessibility Regulations
A9: Video/media | B9: Design system | C9: Linux | D9: Students/learners | E9: Legacy / frozen | G9: BITV 2.0 | H9: Third-party content exception | I9: Design | J9: Component-level accessibility tests | M9: ='Legal Register'!D9 -> Sweden — Act (2018:1937) on accessibility to digital public services
A10: Design system/component library | B10: Vendor service | C10: Cross-platform desktop | D10: Patients/service users | E10: Being replaced | G10: JIS X 8341-3:2016 | H10: Alternative accessible format / method used | I10: UX research | J10: End-to-end accessibility tests | M10: ='Legal Register'!D10 -> Finland — Act on the Provision of Digital Services (306/2019)
A11: Third-party service/widget | B11: Other | C11: PDF | D11: Developers | E11: Retiring / sunset | G11: KS 2952 (Kenya ICT Accessibility Standard) | H11: Temporary exception with remediation date | I11: Content design | J11: Expert audit | M11: ='Legal Register'!D11 -> Denmark — Web Accessibility Act
A12: Authentication/identity | C12: Office document | D12: Public-sector users | E12: Procured / vendor-hosted | G12: AODA / WCAG 2.0 AA | H12: Not applicable | I12: QA / test engineering | J12: Testing with disabled users | M12: ='Legal Register'!D12 -> Belgium — Law on accessibility of websites and mobile applications of public bodies (2018)
A13: Payment/checkout | C13: Email client | D13: Mixed audience | G13: NZ Government Web Accessibility Standard | H13: Unknown / pending review | I13: Accessibility specialist | J13: Vendor accessibility evidence | M13: ='Legal Register'!D13 -> Netherlands — public-sector digital accessibility decree/rules
A14: Kiosk/self-service terminal | C14: Kiosk/embedded | D14: Other | G14: Internal accessibility standard | I14: Accessibility program / Centre of Excellence | J14: VPAT / ACR review | M14: ='Legal Register'!D14 -> Poland — Act of 4 April 2019 on digital accessibility
A15: Internal tool | C15: Hardware/firmware | G15: Contractual/vendor accessibility standard | I15: Design system team | J15: Accessibility statement / conformance report | M15: ='Legal Register'!D15 -> Portugal — Decreto-Lei n.º 83/2018
A16: Intranet/extranet | C16: Multiple platforms | G16: Platform accessibility guidance | I16: Security | J16: Procurement acceptance testing | M16: ='Legal Register'!D16 -> UK — Public Sector Bodies Accessibility Regulations 2018
A17: SaaS platform | C17: Other | G17: To be determined | I17: Privacy / data protection | J17: Combination of methods | M17: ='Legal Register'!D17 -> UK — Equality Act 2010
A18: Hardware/ICT product | I18: Legal / compliance | J18: Not yet defined | M18: ='Legal Register'!D18 -> US — Americans with Disabilities Act (ADA)
A19: API/developer portal | I19: Procurement / vendor management | M19: ='Legal Register'!D19 -> US — ADA Title II Web & Mobile Accessibility Rule (2024)
A20: AI/agent interface | I20: IT / internal systems | M20: ='Legal Register'!D20 -> US — Section 508 of the Rehabilitation Act
A21: Other | I21: Marketing / communications | M21: ='Legal Register'!D21 -> US — Air Carrier Access Act web/kiosk accessibility rule
I22: Document production | M22: ='Legal Register'!D22 -> US — 21st Century Communications and Video Accessibility Act (CVAA)
I23: Customer support | M23: ='Legal Register'!D23 -> Canada — Accessible Canada Act (ACA)
I24: Operations | M24: ='Legal Register'!D24 -> Canada — CAN/ASC-EN 301 549:2024
I25: Executive sponsor | M25: ='Legal Register'!D25 -> Ontario — AODA web accessibility requirements
I26: Vendor / supplier | M26: ='Legal Register'!D26 -> Australia — Disability Discrimination Act 1992 (DDA)
I27: Shared ownership | M27: ='Legal Register'!D27 -> Australia — Digital Experience Policy / Digital Service Standard
M28: ='Legal Register'!D28 -> Australia — Commonwealth Procurement Rules + AS EN 301 549
M29: ='Legal Register'!D29 -> New Zealand — Human Rights Act 1993
M30: ='Legal Register'!D30 -> New Zealand — Government Web Accessibility Standard
M31: ='Legal Register'!D31 -> Japan — Act for Eliminating Discrimination against Persons with Disabilities
M32: ='Legal Register'!D32 -> Japan — JIS X 8341-3:2016 + Everyone's Public Website Guidelines
M33: ='Legal Register'!D33 -> India — Rights of Persons with Disabilities Act 2016
M34: ='Legal Register'!D34 -> India — Guidelines for Indian Government Websites / Apps (GIGW)
M35: ='Legal Register'!D35 -> Republic of Korea — disability accessibility framework
M36: ='Legal Register'!D36 -> China — Law on Protection of Persons with Disabilities + digital accessibility standards
M37: ='Legal Register'!D37 -> Hong Kong — Government web accessibility guidance
M38: ='Legal Register'!D38 -> Israel — Equal Rights for Persons with Disabilities framework + web accessibility regulations
M39: ='Legal Register'!D39 -> Brazil — Brazilian Law of Inclusion (Law No. 13.146/2015)
... M44: ='Legal Register'!D44 -> South Africa — Government Website Accessibility Guidelines

Sheet Reporting
A1: Accessibility scope: reporting
A2: All figures are live formulas over the Accessibility Inventory sheet (rows 2-1000). Percentages are of assets recorded.
A4: Headline totals
A5: Measure | B5: Count | C5: % of assets
A6: Assets recorded | B6: =COUNTA('Accessibility Inventory'!$A$2:$A$1000) -> 4
A7: In scope | B7: =COUNTIF('Accessibility Inventory'!$H$2:$H$1000,"In scope") -> 3 | C7: =IF($B$6=0,0,B7/$B$6) -> 0.75
A8: Partially in scope | B8: =COUNTIF('Accessibility Inventory'!$H$2:$H$1000,"Partially in scope") -> 0 | C8: =IF($B$6=0,0,B8/$B$6) -> 0
A9: Pending assessment | B9: =COUNTIF('Accessibility Inventory'!$H$2:$H$1000,"Pending assessment") -> 1 | C9: =IF($B$6=0,0,B9/$B$6) -> 0.25
A10: Out of scope (documented basis) | B10: =COUNTIF('Accessibility Inventory'!$H$2:$H$1000,"Out of scope — documented basis") -> 0 | C10: =IF($B$6=0,0,B10/$B$6) -> 0
A11: Critical or High criticality | B11: =COUNTIF('Accessibility Inventory'!$R$2:$R$1000,"Critical*")+COUNTIF('Accessibility Inventory'!$R$2:$R$1000,"High*") -> 4 | C11: =IF($B$6=0,0,B11/$B$6) -> 1
A12: Exception flagged (anything other than none / not applicable) | B12: =COUNTA('Accessibility Inventory'!$M$2:$M$1000)-COUNTIF('Accessibility Inventory'!$M$2:$M$1000,"None identified")-COUNTIF('Accessibility Inventory'!$M$2:$M$1000,"Not applicable") -> 3 | C12: =IF($B$6=0,0,B12/$B$6) -> 0.75
A14: Completeness checks (assets missing key data)
A15: Check | B15: Assets | C15: % of assets
A16: No primary legal / policy regime | B16: =$B$6-COUNTIFS('Accessibility Inventory'!$A$2:$A$1000,"<>",'Accessibility Inventory'!$I$2:$I$1000,"<>") -> 0 | C16: =IF($B$6=0,0,B16/$B$6) -> 0
A17: No accessibility baseline | B17: =$B$6-COUNTIFS('Accessibility Inventory'!$A$2:$A$1000,"<>",'Accessibility Inventory'!$L$2:$L$1000,"<>") -> 0 | C17: =IF($B$6=0,0,B17/$B$6) -> 0
A18: No primary owner | B18: =$B$6-COUNTIFS('Accessibility Inventory'!$A$2:$A$1000,"<>",'Accessibility Inventory'!$O$2:$O$1000,"<>") -> 0 | C18: =IF($B$6=0,0,B18/$B$6) -> 0
A19: No criticality set | B19: =$B$6-COUNTIFS('Accessibility Inventory'!$A$2:$A$1000,"<>",'Accessibility Inventory'!$R$2:$R$1000,"<>") -> 0 | C19: =IF($B$6=0,0,B19/$B$6) -> 0
A20: No verification method | B20: =$B$6-COUNTIFS('Accessibility Inventory'!$A$2:$A$1000,"<>",'Accessibility Inventory'!$Q$2:$Q$1000,"<>") -> 0 | C20: =IF($B$6=0,0,B20/$B$6) -> 0
A21: No target / review date | B21: =$B$6-COUNTIFS('Accessibility Inventory'!$A$2:$A$1000,"<>",'Accessibility Inventory'!$T$2:$T$1000,"<>") -> 4 | C21: =IF($B$6=0,0,B21/$B$6) -> 1
A22: No scope status | B22: =$B$6-COUNTIFS('Accessibility Inventory'!$A$2:$A$1000,"<>",'Accessibility Inventory'!$H$2:$H$1000,"<>") -> 0 | C22: =IF($B$6=0,0,B22/$B$6) -> 0
A23: Verification "Not yet defined" | B23: =COUNTIF('Accessibility Inventory'!$Q$2:$Q$1000,"Not yet defined") -> 0 | C23: =IF($B$6=0,0,B23/$B$6) -> 0
A24: Exception flagged but no basis recorded | B24: =SUMPRODUCT(('Accessibility Inventory'!$M$2:$M$1000<>"")*('Accessibility Inventory'!$M$2:$M$1000<>"None identified")*('Accessibility Inventory'!$M$2:$M$1000<>"Not applicable")*('Accessibility Inventory'!$N$2:$N$1000="")) -> 1 | C24: =IF($B$6=0,0,B24/$B$6) -> 0.25
A25: Review date in the past | B25: =COUNTIFS('Accessibility Inventory'!$T$2:$T$1000,"<"&TODAY(),'Accessibility Inventory'!$T$2:$T$1000,">0") -> 0 | C25: =IF($B$6=0,0,B25/$B$6) -> 0
A27: Breakdowns
A28: Scope status
A29: Value | B29: Assets | C29: % of assets
A30: =Lookups!F2 -> In scope | B30: =COUNTIF('Accessibility Inventory'!$H$2:$H$1000,A30) -> 3 | C30: =IF($B$6=0,0,B30/$B$6) -> 0.75
A31: =Lookups!F3 -> Out of scope — documented basis | B31: =COUNTIF('Accessibility Inventory'!$H$2:$H$1000,A31) -> 0 | C31: =IF($B$6=0,0,B31/$B$6) -> 0
A32: =Lookups!F4 -> Pending assessment | B32: =COUNTIF('Accessibility Inventory'!$H$2:$H$1000,A32) -> 1 | C32: =IF($B$6=0,0,B32/$B$6) -> 0.25
A33: =Lookups!F5 -> Partially in scope | B33: =COUNTIF('Accessibility Inventory'!$H$2:$H$1000,A33) -> 0 | C33: =IF($B$6=0,0,B33/$B$6) -> 0
A34: Not set / other | B34: =$B$6-SUM(B30:B33) -> 0 | C34: =IF($B$6=0,0,B34/$B$6) -> 0
A37: Category
A38: Value | B38: Assets | C38: % of assets
A39: =Lookups!A2 -> Public website | B39: =COUNTIF('Accessibility Inventory'!$C$2:$C$1000,A39) -> 1 | C39: =IF($B$6=0,0,B39/$B$6) -> 0.25
A40: =Lookups!A3 -> Web application | B40: =COUNTIF('Accessibility Inventory'!$C$2:$C$1000,A40) -> 1 | C40: =IF($B$6=0,0,B40/$B$6) -> 0.25
A41: =Lookups!A4 -> Native mobile app | B41: =COUNTIF('Accessibility Inventory'!$C$2:$C$1000,A41) -> 0 | C41: =IF($B$6=0,0,B41/$B$6) -> 0
A42: =Lookups!A5 -> Hybrid mobile app | B42: =COUNTIF('Accessibility Inventory'!$C$2:$C$1000,A42) -> 0 | C42: =IF($B$6=0,0,B42/$B$6) -> 0
A43: =Lookups!A6 -> Desktop application | B43: =COUNTIF('Accessibility Inventory'!$C$2:$C$1000,A43) -> 0 | C43: =IF($B$6=0,0,B43/$B$6) -> 0
A44: =Lookups!A7 -> Document/PDF | B44: =COUNTIF('Accessibility Inventory'!$C$2:$C$1000,A44) -> 0 | C44: =IF($B$6=0,0,B44/$B$6) -> 0
A45: =Lookups!A8 -> Email/template | B45: =COUNTIF('Accessibility Inventory'!$C$2:$C$1000,A45) -> 0 | C45: =IF($B$6=0,0,B45/$B$6) -> 0
...

Sheet Review Log
A1: # | B1: Area | C1: Where | D1: Finding | E1: Action | F1: Status
A2: 1 | B2: Lookups | C2: Lookups!M (legal regime list) | D2: Every national entry repeated the jurisdiction ("France — France — Article 47…", "Canada — Ontario — Ontario — AODA…"), and the list was hardcoded text that could drift from the Legal Register. | E2: Column M now reads Legal Register column D by formula. Existing inventory entries (I2:K5) were updated to the new labels. | F2: Fixed
A3: 2 | B3: Inventory | C3: Accessibility Inventory!L3 | D3: Payment checkout cites the ADA Title II web rule but the baseline was EN 301 549. The Title II rule sets WCAG 2.1 Level AA. | E3: Baseline changed to WCAG 2.1 Level AA (original: EN 301 549 (current applicable version)). | F3: Fixed
A4: 3 | B4: Lookups | C4: Lookups!E (Lifecycle) | D4: "Pilot / beta" sat after "Procured / vendor-hosted", out of lifecycle order. | E4: Reordered into lifecycle sequence. No values added or removed. | F4: Fixed
A5: 4 | B5: Validation | C5: Inventory dropdowns | D5: The original cross-sheet dropdowns used an Excel extension some tools drop, and they had no error message, so any text was accepted silently. | E5: Dropdowns recreated as standard validation with a warning message (invalid entries allowed after confirming). | F5: Fixed
A6: 5 | B6: Inventory | C6: Accessibility Inventory!N5 | D6: Row 5 is flagged "Potential exemption / exception" but has no basis recorded. | E6: Left as is. Add the basis or change the status. | F6: Needs decision
A7: 6 | B7: Inventory | C7: Accessibility Inventory!L2 | D7: Row 2 relies on the EAA with a WCAG 2.2 AA baseline. Reasonable target, but EN 301 549 is the designated technical standard for the EAA and is not recorded. | E7: Consider recording EN 301 549 as the baseline, with WCAG 2.2 AA as the internal target. | F7: Needs decision
A8: 7 | B8: Lookups | C8: Lookups!G (Baseline) | D8: "EN 301 549 (current applicable version)" and "RGAA (current version)" are ambiguous. EN 301 549 V4.1.1 was published 2 Sep 2026 (WCAG 2.2 AA basis) but is not yet cited in the EU Official Journal for the EAA; V3.2.1 (WCAG 2.1 AA basis) remains the harmonised version for the Web Accessibility Directive. | E8: Replace with explicit version values (e.g. EN 301 549 V3.2.1, V4.1.1) so reporting shows which version each asset targets. | F8: Needs decision
A9: 8 | B9: Lookups | C9: Lookups!H (Exception status) | D9: The list mixes statuses (None identified, Unknown, Not applicable), claimed grounds (disproportionate burden, fundamental alteration, microenterprise, third-party content) and mitigations ("Alternative accessible format", "Temporary exception with remediation date"). The last two are not legal exemptions. | E9: Split into a Status column and a Basis-type column, or rename the last two as internal risk-acceptance entries. | F9: Needs decision
A10: 9 | B10: Lookups | C10: Lookups!B, C, E, L | D10: Several lists mix dimensions: Product scope includes "Design system" and "Vendor service"; Platform includes file formats (PDF, Office document); Lifecycle includes "Procured / vendor-hosted"; Dependency has both "Third-party" and "Vendor-hosted". Rows can be classified two ways. | E10: Keep each list to one dimension (size, type, platform, sourcing) so counts in Reporting are not double-described. | F10: Needs decision
A11: 10 | B11: Lookups | C11: Lookups!I (Owner / team) | D11: "Shared ownership", "Executive sponsor" and "Vendor / supplier" are selectable as owner. This works against a single accountable internal owner, especially for procured assets. | E11: Remove them from the owner list, or move them to a separate Sponsor / Supplier column. | F11: Needs decision
A12: 11 | B12: Inventory | C12: Accessibility Inventory!S | D12: Column is titled "Dependency / vendor" but the list holds types only. Vendor names have nowhere to go except Notes. | E12: Add a Vendor name column, or retitle to "Dependency type". | F12: Needs decision
A13: 12 | B13: Lookups | C13: Lookups!J (Verification) | D13: "Combination of methods" hides which methods are used (2 of 4 rows). "Vendor accessibility evidence" overlaps "VPAT / ACR review". "Accessibility statement / conformance report" is a document, not a method. | E13: Record the methods separately, or add a Notes convention. Merge the overlapping entries. | F13: Needs decision
... A22: 21 | B22: Data | C22: Accessibility Inventory | D22: Four example rows (2-5), all marked as examples. Table is sized to row 250; Reporting reads rows 2-1000. | E22: No action. Replace examples with real assets. | F22: Info
B24: Status counts
B25: Fixed | C25: =COUNTIF($F$2:$F$22,B25) -> 4
B26: Needs decision | C26: =COUNTIF($F$2:$F$22,B26) -> 8
B27: Needs verification | C27: =COUNTIF($F$2:$F$22,B27) -> 7
B28: Coverage note | C28: =COUNTIF($F$2:$F$22,B28) -> 1
B29: Info | C29: =COUNTIF($F$2:$F$22,B29) -> 1
